{
  "xsize": 16,
  "zsize": 16,
  "slices": [
    [
      "################",
      "################",
      "################",
      "################",
      "################",
      "################",
      "################",
      "################",
      "################",
      "#######l########",
      "################",
      "################",
      "################",
      "################",
      "################",
      "################"
    ],
    [
      "#aa@aaaaaaaa@aa#",
      "a              a",
      "a              a",
      "@              @",
      "a              a",
      "a             Ca",
      "a    QQQQQ:::::a",
      "a    Q   Q     a",
      "a    Q   Q     a",
      "a      l       a",
      "a    QQQQQ     a",
      "a              a",
      "@              @",
      "a              a",
      "a              a",
      "#aa@aaaaaaaa@aa#"
    ],
    [
      "#aa@aaaaaaaa@aa#",
      "a              a",
      "a              a",
      "@              @",
      "a              a",
      "a              a",
      "a    QQQQQ:::::a",
      "a    Q   Q     a",
      "a    Q   Q     a",
      "a      l       a",
      "a    QQQQQ     a",
      "a              a",
      "@              @",
      "a              a",
      "a              a",
      "#aa@aaaaaaaa@aa#"
    ],
    [
      "#aa@aaaaaaaa@aa#",
      "a              a",
      "a              a",
      "@              @",
      "a              a",
      "a              a",
      "a    QQQQQ:::::a",
      "a    Q   Q     a",
      "a    Q   Q     a",
      "a    Q l Q     a",
      "a    QQQQQ     a",
      "a              a",
      "@              @",
      "a              a",
      "a              a",
      "#aa@aaaaaaaa@aa#"
    ],
    [
      "################",
      "################",
      "################",
      "################",
      "################",
      "################",
      "################",
      "################",
      "################",
      "#######l########",
      "################",
      "################",
      "################",
      "################",
      "################",
      "################"
    ],
    [
      "################",
      "################",
      "################",
      "################",
      "################",
      "################",
      "################",
      "################",
      "################",
      "#######l########",
      "################",
      "################",
      "################",
      "################",
      "################",
      "################"
    ]
  ]
}